Traceback (most recent call last):
  File "c:\users\gordo\appdata\local\pypoetry\cache\virtualenvs\xaod-usage-w68kx7k0-py3.9\lib\site-packages\jupyter_cache\executors\utils.py", line 51, in single_nb_execution
    executenb(
  File "c:\users\gordo\appdata\local\pypoetry\cache\virtualenvs\xaod-usage-w68kx7k0-py3.9\lib\site-packages\nbclient\client.py", line 1093, in execute
    return NotebookClient(nb=nb, resources=resources, km=km, **kwargs).execute()
  File "c:\users\gordo\appdata\local\pypoetry\cache\virtualenvs\xaod-usage-w68kx7k0-py3.9\lib\site-packages\nbclient\util.py", line 84, in wrapped
    return just_run(coro(*args, **kwargs))
  File "c:\users\gordo\appdata\local\pypoetry\cache\virtualenvs\xaod-usage-w68kx7k0-py3.9\lib\site-packages\nbclient\util.py", line 62, in just_run
    return loop.run_until_complete(coro)
  File "C:\Users\gordo\AppData\Local\Programs\Python\Python39\lib\asyncio\base_events.py", line 642, in run_until_complete
    return future.result()
  File "c:\users\gordo\appdata\local\pypoetry\cache\virtualenvs\xaod-usage-w68kx7k0-py3.9\lib\site-packages\nbclient\client.py", line 559, in async_execute
    await self.async_execute_cell(
  File "c:\users\gordo\appdata\local\pypoetry\cache\virtualenvs\xaod-usage-w68kx7k0-py3.9\lib\site-packages\nbclient\client.py", line 854, in async_execute_cell
    self._check_raise_for_error(cell, exec_reply)
  File "c:\users\gordo\appdata\local\pypoetry\cache\virtualenvs\xaod-usage-w68kx7k0-py3.9\lib\site-packages\nbclient\client.py", line 756, in _check_raise_for_error
    raise CellExecutionError.from_cell_and_msg(cell, exec_reply_content)
nbclient.exceptions.CellExecutionError: An error occurred while executing the following cell:
------------------
from func_adl_servicex_xaodr21.xAOD import Jet_v1
help(Jet_v1)
------------------

[1;31m---------------------------------------------------------------------------[0m
[1;31mImportError[0m                               Traceback (most recent call last)
[1;32m~\AppData\Local\Temp/ipykernel_450028/750850761.py[0m in [0;36m<module>[1;34m[0m
[1;32m----> 1[1;33m [1;32mfrom[0m [0mfunc_adl_servicex_xaodr21[0m[1;33m.[0m[0mxAOD[0m [1;32mimport[0m [0mJet_v1[0m[1;33m[0m[1;33m[0m[0m
[0m[0;32m      2[0m [0mhelp[0m[1;33m([0m[0mJet_v1[0m[1;33m)[0m[1;33m[0m[1;33m[0m[0m

[1;31mImportError[0m: cannot import name 'Jet_v1' from 'func_adl_servicex_xaodr21.xAOD' (C:\Users\gordo\Code\iris-hep\func_adl_servicex_xaodr21\func_adl_servicex_xaodr21\xAOD\__init__.py)
ImportError: cannot import name 'Jet_v1' from 'func_adl_servicex_xaodr21.xAOD' (C:\Users\gordo\Code\iris-hep\func_adl_servicex_xaodr21\func_adl_servicex_xaodr21\xAOD\__init__.py)

