Traceback (most recent call last):
  File "C:\Users\gordo\AppData\Local\pypoetry\Cache\virtualenvs\xaod-usage-w68Kx7k0-py3.9\lib\site-packages\jupyter_cache\executors\utils.py", line 51, in single_nb_execution
    executenb(
  File "C:\Users\gordo\AppData\Local\pypoetry\Cache\virtualenvs\xaod-usage-w68Kx7k0-py3.9\lib\site-packages\nbclient\client.py", line 1117, in execute
    return NotebookClient(nb=nb, resources=resources, km=km, **kwargs).execute()
  File "C:\Users\gordo\AppData\Local\pypoetry\Cache\virtualenvs\xaod-usage-w68Kx7k0-py3.9\lib\site-packages\nbclient\util.py", line 78, in wrapped
    return just_run(coro(*args, **kwargs))
  File "C:\Users\gordo\AppData\Local\pypoetry\Cache\virtualenvs\xaod-usage-w68Kx7k0-py3.9\lib\site-packages\nbclient\util.py", line 57, in just_run
    return loop.run_until_complete(coro)
  File "C:\Users\gordo\AppData\Local\Programs\Python\Python39\lib\asyncio\base_events.py", line 642, in run_until_complete
    return future.result()
  File "C:\Users\gordo\AppData\Local\pypoetry\Cache\virtualenvs\xaod-usage-w68Kx7k0-py3.9\lib\site-packages\nbclient\client.py", line 558, in async_execute
    await self.async_execute_cell(
  File "C:\Users\gordo\AppData\Local\pypoetry\Cache\virtualenvs\xaod-usage-w68Kx7k0-py3.9\lib\site-packages\nbclient\client.py", line 862, in async_execute_cell
    self._check_raise_for_error(cell, exec_reply)
  File "C:\Users\gordo\AppData\Local\pypoetry\Cache\virtualenvs\xaod-usage-w68Kx7k0-py3.9\lib\site-packages\nbclient\client.py", line 765, in _check_raise_for_error
    raise CellExecutionError.from_cell_and_msg(cell, exec_reply_content)
nbclient.exceptions.CellExecutionError: An error occurred while executing the following cell:
------------------
import matplotlib.pyplot as plt
from config import ds_jz2_exot15 as ds
import numpy as np
import pandas as pd
from particle import Particle
from hist import Hist

pd.options.display.max_rows = None
------------------

[1;31m---------------------------------------------------------------------------[0m
[1;31mModuleNotFoundError[0m                       Traceback (most recent call last)
[1;32m~\AppData\Local\Temp/ipykernel_23528/1264332153.py[0m in [0;36m<module>[1;34m[0m
[0;32m      3[0m [1;32mimport[0m [0mnumpy[0m [1;32mas[0m [0mnp[0m[1;33m[0m[1;33m[0m[0m
[0;32m      4[0m [1;32mimport[0m [0mpandas[0m [1;32mas[0m [0mpd[0m[1;33m[0m[1;33m[0m[0m
[1;32m----> 5[1;33m [1;32mfrom[0m [0mparticle[0m [1;32mimport[0m [0mParticle[0m[1;33m[0m[1;33m[0m[0m
[0m[0;32m      6[0m [1;32mfrom[0m [0mhist[0m [1;32mimport[0m [0mHist[0m[1;33m[0m[1;33m[0m[0m
[0;32m      7[0m [1;33m[0m[0m

[1;31mModuleNotFoundError[0m: No module named 'particle'
ModuleNotFoundError: No module named 'particle'

